2016-10-18 15:04:22,077 - arteria.web.app - INFO - Logger initialized by AppService
2016-10-18 15:04:22,089 - delivery.repositories.runfolder_repository - DEBUG - Listing dirs in: /home/MOLMED/johda411/workspace/arteria/arteria-delivery/tests/integration_tests/resources
2016-10-18 15:04:22,089 - tornado.application - ERROR - Uncaught exception GET /api/1.0/runfolders (127.0.0.1)
HTTPServerRequest(protocol='http', host='localhost:40983', method='GET', uri='/api/1.0/runfolders', version='HTTP/1.1', remote_ip='127.0.0.1', headers={'Connection': 'close', 'Host': 'localhost:40983', 'Accept-Encoding': 'gzip'})
Traceback (most recent call last):
  File "/home/MOLMED/johda411/miniconda2/envs/arteria-delivery/lib/python2.7/site-packages/tornado/web.py", line 1413, in _execute
    result = method(*self.path_args, **self.path_kwargs)
  File "/home/MOLMED/johda411/workspace/arteria/arteria-delivery/delivery/handlers/runfolder_handlers.py", line 26, in get
    self.runfolder_repo.get_runfolders()))
  File "/home/MOLMED/johda411/workspace/arteria/arteria-delivery/delivery/repositories/runfolder_repository.py", line 43, in _get_runfolders
    for directory in directories:
  File "/home/MOLMED/johda411/workspace/arteria/arteria-delivery/delivery/repositories/runfolder_repository.py", line 17, in _list_directories
    for my_dir in os.listdir(base_path):
OSError: [Errno 2] No such file or directory: 'resources/'
2016-10-18 15:04:22,092 - tornado.access - ERROR - 500 GET /api/1.0/runfolders (127.0.0.1) 4.20ms
2016-10-18 15:04:37,346 - arteria.web.app - INFO - Logger initialized by AppService
2016-10-18 15:04:37,358 - delivery.repositories.runfolder_repository - DEBUG - Listing dirs in: /home/MOLMED/johda411/workspace/arteria/arteria-delivery/tests/integration_tests/resources
2016-10-18 15:04:37,358 - tornado.application - ERROR - Uncaught exception GET /api/1.0/runfolders (127.0.0.1)
HTTPServerRequest(protocol='http', host='localhost:36177', method='GET', uri='/api/1.0/runfolders', version='HTTP/1.1', remote_ip='127.0.0.1', headers={'Connection': 'close', 'Host': 'localhost:36177', 'Accept-Encoding': 'gzip'})
Traceback (most recent call last):
  File "/home/MOLMED/johda411/miniconda2/envs/arteria-delivery/lib/python2.7/site-packages/tornado/web.py", line 1413, in _execute
    result = method(*self.path_args, **self.path_kwargs)
  File "/home/MOLMED/johda411/workspace/arteria/arteria-delivery/delivery/handlers/runfolder_handlers.py", line 26, in get
    self.runfolder_repo.get_runfolders()))
  File "/home/MOLMED/johda411/workspace/arteria/arteria-delivery/delivery/repositories/runfolder_repository.py", line 43, in _get_runfolders
    for directory in directories:
  File "/home/MOLMED/johda411/workspace/arteria/arteria-delivery/delivery/repositories/runfolder_repository.py", line 17, in _list_directories
    for my_dir in os.listdir(base_path):
OSError: [Errno 2] No such file or directory: 'resources/'
2016-10-18 15:04:37,361 - tornado.access - ERROR - 500 GET /api/1.0/runfolders (127.0.0.1) 4.26ms
